Workbook

Sheet タスク
A1: root@team:~# ./task_control --all
A2: 薄い青灰色のセルが入力欄。No/顧客/アラート/実績工数は自動。状態を「完了」にできるのはメンターのみ(新人は「レビュー待ち」まで)。例の5行は消して使う。
A3: No | B3: 顧客 | C3: 案件 | D3: タスク名 | E3: 担当 | F3: 開始日 | G3: 期限 | H3: 状態 | I3: 進捗% | J3: アラート | K3: 予定工数h | L3: 実績工数h | M3: 完了の定義 | N3: メモ | O3: 登録日 | P3: 完了日
A4: =IF(D4="","",ROW()-3) -> 1 | B4: =IF($C4="","",IFERROR(INDEX(案件マスタ!$A$4:$A$23,MATCH($C4,案件マスタ!$B$4:$B$23,0)),"?")) -> A社 | C4: A社_無線LAN更改 | D4: 現地調査結果のまとめ | E4: 新人A | F4: 46266 | G4: 46270 | H4: 進行中 | I4: 0.4 | J4: =IF(D4="","",IF(H4="完了","✓ DONE",IF(G4="","⚠ NO DUE",IF(G4<TODAY(),"🔴 OVERDUE",IF(G4=TODAY(),"🟡 TODAY",""))))) -> 🔴 OVERDUE | K4: 8 | L4: =IF(A4="","",SUMIFS(工数ログ!$E$4:$E$1003,工数ログ!$D$4:$D$1003,$A4)) -> 5.5 | M4: 調査結果をExcelにまとめ、抜けがないかメンター確認 | O4: 46264
A5: =IF(D5="","",ROW()-3) -> 2 | B5: =IF($C5="","",IFERROR(INDEX(案件マスタ!$A$4:$A$23,MATCH($C5,案件マスタ!$B$4:$B$23,0)),"?")) -> A社 | C5: A社_無線LAN更改 | D5: 機器設定パラメータシート作成 | E5: 新人A | F5: 46269 | G5: 46273 | H5: レビュー待ち | I5: 0.9 | J5: =IF(D5="","",IF(H5="完了","✓ DONE",IF(G5="","⚠ NO DUE",IF(G5<TODAY(),"🔴 OVERDUE",IF(G5=TODAY(),"🟡 TODAY",""))))) -> 🟡 TODAY | K5: 12 | L5: =IF(A5="","",SUMIFS(工数ログ!$E$4:$E$1003,工数ログ!$D$4:$D$1003,$A5)) -> 2 | M5: テンプレ全項目を埋めてレビュー依頼 | O5: 46266
A6: =IF(D6="","",ROW()-3) -> 3 | B6: =IF($C6="","",IFERROR(INDEX(案件マスタ!$A$4:$A$23,MATCH($C6,案件マスタ!$B$4:$B$23,0)),"?")) -> A社 | C6: A社_FW更改 | D6: 検証構成図の作成 | E6: 新人B | F6: 46272 | G6: 46277 | H6: 進行中 | I6: 0.3 | J6: =IF(D6="","",IF(H6="完了","✓ DONE",IF(G6="","⚠ NO DUE",IF(G6<TODAY(),"🔴 OVERDUE",IF(G6=TODAY(),"🟡 TODAY",""))))) | K6: 6 | L6: =IF(A6="","",SUMIFS(工数ログ!$E$4:$E$1003,工数ログ!$D$4:$D$1003,$A6)) -> 1.5 | M6: 検証ラボの物理・論理構成図を作成 | O6: 46269
A7: =IF(D7="","",ROW()-3) -> 4 | B7: =IF($C7="","",IFERROR(INDEX(案件マスタ!$A$4:$A$23,MATCH($C7,案件マスタ!$B$4:$B$23,0)),"?")) -> B社 | C7: B社_監視導入 | D7: 監視項目一覧のドラフト | E7: 新人B | F7: 46267 | G7: 46270 | H7: 完了 | I7: 1 | J7: =IF(D7="","",IF(H7="完了","✓ DONE",IF(G7="","⚠ NO DUE",IF(G7<TODAY(),"🔴 OVERDUE",IF(G7=TODAY(),"🟡 TODAY",""))))) -> ✓ DONE | K7: 4 | L7: =IF(A7="","",SUMIFS(工数ログ!$E$4:$E$1003,工数ログ!$D$4:$D$1003,$A7)) -> 4 | M7: 監視対象と閾値の一覧を作成 | O7: 46266 | P7: 46270
A8: =IF(D8="","",ROW()-3) -> 5 | B8: =IF($C8="","",IFERROR(INDEX(案件マスタ!$A$4:$A$23,MATCH($C8,案件マスタ!$B$4:$B$23,0)),"?")) -> B社 | C8: B社_監視導入 | D8: 死活監視の検証 | E8: 新人A | F8: 46274 | G8: 46281 | H8: 未着手 | I8: 0 | J8: =IF(D8="","",IF(H8="完了","✓ DONE",IF(G8="","⚠ NO DUE",IF(G8<TODAY(),"🔴 OVERDUE",IF(G8=TODAY(),"🟡 TODAY",""))))) | K8: 10 | L8: =IF(A8="","",SUMIFS(工数ログ!$E$4:$E$1003,工数ログ!$D$4:$D$1003,$A8)) -> 0 | M8: 検証ラボでポーリング動作を確認しエビデンス取得 | O8: 46272
A9: =IF(D9="","",ROW()-3) | B9: =IF($C9="","",IFERROR(INDEX(案件マスタ!$A$4:$A$23,MATCH($C9,案件マスタ!$B$4:$B$23,0)),"?")) | J9: =IF(D9="","",IF(H9="完了","✓ DONE",IF(G9="","⚠ NO DUE",IF(G9<TODAY(),"🔴 OVERDUE",IF(G9=TODAY(),"🟡 TODAY",""))))) | L9: =IF(A9="","",SUMIFS(工数ログ!$E$4:$E$1003,工数ログ!$D$4:$D$1003,$A9))
A10: =IF(D10="","",ROW()-3) | B10: =IF($C10="","",IFERROR(INDEX(案件マスタ!$A$4:$A$23,MATCH($C10,案件マスタ!$B$4:$B$23,0)),"?")) | J10: =IF(D10="","",IF(H10="完了","✓ DONE",IF(G10="","⚠ NO DUE",IF(G10<TODAY(),"🔴 OVERDUE",IF(G10=TODAY(),"🟡 TODAY",""))))) | L10: =IF(A10="","",SUMIFS(工数ログ!$E$4:$E$1003,工数ログ!$D$4:$D$1003,$A10))
A11: =IF(D11="","",ROW()-3) | B11: =IF($C11="","",IFERROR(INDEX(案件マスタ!$A$4:$A$23,MATCH($C11,案件マスタ!$B$4:$B$23,0)),"?")) | J11: =IF(D11="","",IF(H11="完了","✓ DONE",IF(G11="","⚠ NO DUE",IF(G11<TODAY(),"🔴 OVERDUE",IF(G11=TODAY(),"🟡 TODAY",""))))) | L11: =IF(A11="","",SUMIFS(工数ログ!$E$4:$E$1003,工数ログ!$D$4:$D$1003,$A11))
A12: =IF(D12="","",ROW()-3) | B12: =IF($C12="","",IFERROR(INDEX(案件マスタ!$A$4:$A$23,MATCH($C12,案件マスタ!$B$4:$B$23,0)),"?")) | J12: =IF(D12="","",IF(H12="完了","✓ DONE",IF(G12="","⚠ NO DUE",IF(G12<TODAY(),"🔴 OVERDUE",IF(G12=TODAY(),"🟡 TODAY",""))))) | L12: =IF(A12="","",SUMIFS(工数ログ!$E$4:$E$1003,工数ログ!$D$4:$D$1003,$A12))
A13: =IF(D13="","",ROW()-3) | B13: =IF($C13="","",IFERROR(INDEX(案件マスタ!$A$4:$A$23,MATCH($C13,案件マスタ!$B$4:$B$23,0)),"?")) | J13: =IF(D13="","",IF(H13="完了","✓ DONE",IF(G13="","⚠ NO DUE",IF(G13<TODAY(),"🔴 OVERDUE",IF(G13=TODAY(),"🟡 TODAY",""))))) | L13: =IF(A13="","",SUMIFS(工数ログ!$E$4:$E$1003,工数ログ!$D$4:$D$1003,$A13))
A14: =IF(D14="","",ROW()-3) | B14: =IF($C14="","",IFERROR(INDEX(案件マスタ!$A$4:$A$23,MATCH($C14,案件マスタ!$B$4:$B$23,0)),"?")) | J14: =IF(D14="","",IF(H14="完了","✓ DONE",IF(G14="","⚠ NO DUE",IF(G14<TODAY(),"🔴 OVERDUE",IF(G14=TODAY(),"🟡 TODAY",""))))) | L14: =IF(A14="","",SUMIFS(工数ログ!$E$4:$E$1003,工数ログ!$D$4:$D$1003,$A14))
A15: =IF(D15="","",ROW()-3) | B15: =IF($C15="","",IFERROR(INDEX(案件マスタ!$A$4:$A$23,MATCH($C15,案件マスタ!$B$4:$B$23,0)),"?")) | J15: =IF(D15="","",IF(H15="完了","✓ DONE",IF(G15="","⚠ NO DUE",IF(G15<TODAY(),"🔴 OVERDUE",IF(G15=TODAY(),"🟡 TODAY",""))))) | L15: =IF(A15="","",SUMIFS(工数ログ!$E$4:$E$1003,工数ログ!$D$4:$D$1003,$A15))
A16: =IF(D16="","",ROW()-3) | B16: =IF($C16="","",IFERROR(INDEX(案件マスタ!$A$4:$A$23,MATCH($C16,案件マスタ!$B$4:$B$23,0)),"?")) | J16: =IF(D16="","",IF(H16="完了","✓ DONE",IF(G16="","⚠ NO DUE",IF(G16<TODAY(),"🔴 OVERDUE",IF(G16=TODAY(),"🟡 TODAY",""))))) | L16: =IF(A16="","",SUMIFS(工数ログ!$E$4:$E$1003,工数ログ!$D$4:$D$1003,$A16))
A17: =IF(D17="","",ROW()-3) | B17: =IF($C17="","",IFERROR(INDEX(案件マスタ!$A$4:$A$23,MATCH($C17,案件マスタ!$B$4:$B$23,0)),"?")) | J17: =IF(D17="","",IF(H17="完了","✓ DONE",IF(G17="","⚠ NO DUE",IF(G17<TODAY(),"🔴 OVERDUE",IF(G17=TODAY(),"🟡 TODAY",""))))) | L17: =IF(A17="","",SUMIFS(工数ログ!$E$4:$E$1003,工数ログ!$D$4:$D$1003,$A17))
A18: =IF(D18="","",ROW()-3) | B18: =IF($C18="","",IFERROR(INDEX(案件マスタ!$A$4:$A$23,MATCH($C18,案件マスタ!$B$4:$B$23,0)),"?")) | J18: =IF(D18="","",IF(H18="完了","✓ DONE",IF(G18="","⚠ NO DUE",IF(G18<TODAY(),"🔴 OVERDUE",IF(G18=TODAY(),"🟡 TODAY",""))))) | L18: =IF(A18="","",SUMIFS(工数ログ!$E$4:$E$1003,工数ログ!$D$4:$D$1003,$A18))
A19: =IF(D19="","",ROW()-3) | B19: =IF($C19="","",IFERROR(INDEX(案件マスタ!$A$4:$A$23,MATCH($C19,案件マスタ!$B$4:$B$23,0)),"?")) | J19: =IF(D19="","",IF(H19="完了","✓ DONE",IF(G19="","⚠ NO DUE",IF(G19<TODAY(),"🔴 OVERDUE",IF(G19=TODAY(),"🟡 TODAY",""))))) | L19: =IF(A19="","",SUMIFS(工数ログ!$E$4:$E$1003,工数ログ!$D$4:$D$1003,$A19))
A20: =IF(D20="","",ROW()-3) | B20: =IF($C20="","",IFERROR(INDEX(案件マスタ!$A$4:$A$23,MATCH($C20,案件マスタ!$B$4:$B$23,0)),"?")) | J20: =IF(D20="","",IF(H20="完了","✓ DONE",IF(G20="","⚠ NO DUE",IF(G20<TODAY(),"🔴 OVERDUE",IF(G20=TODAY(),"🟡 TODAY",""))))) | L20: =IF(A20="","",SUMIFS(工数ログ!$E$4:$E$1003,工数ログ!$D$4:$D$1003,$A20))
... A503: =IF(D503="","",ROW()-3) | B503: =IF($C503="","",IFERROR(INDEX(案件マスタ!$A$4:$A$23,MATCH($C503,案件マスタ!$B$4:$B$23,0)),"?")) | J503: =IF(D503="","",IF(H503="完了","✓ DONE",IF(G503="","⚠ NO DUE",IF(G503<TODAY(),"🔴 OVERDUE",IF(G503=TODAY(),"🟡 TODAY",""))))) | L503: =IF(A503="","",SUMIFS(工数ログ!$E$4:$E$1003,工数ログ!$D$4:$D$1003,$A503))

Sheet ガント
A1: root@team:~# ./gantt --days 70
A2: 表示開始日→ | C2: 46266 | E2: 予定 | F2: 実績 | G2: ▶進捗位置 | H2: 今日 | I2: 完了
E3: ▶(赤)が「今日」の列より左にある行 = 進捗が遅れている。縦に眺めればイナズマ線と同じ読み方。
I4: =TEXT(I$5,"m月") -> 9月 | J4: =IF(DAY(J$5)=1,TEXT(J$5,"m月"),"") | K4: =IF(DAY(K$5)=1,TEXT(K$5,"m月"),"") | L4: =IF(DAY(L$5)=1,TEXT(L$5,"m月"),"") | M4: =IF(DAY(M$5)=1,TEXT(M$5,"m月"),"") | N4: =IF(DAY(N$5)=1,TEXT(N$5,"m月"),"") | O4: =IF(DAY(O$5)=1,TEXT(O$5,"m月"),"") | P4: =IF(DAY(P$5)=1,TEXT(P$5,"m月"),"") | Q4: =IF(DAY(Q$5)=1,TEXT(Q$5,"m月"),"") | ... BZ4: =IF(DAY(BZ$5)=1,TEXT(BZ$5,"m月"),"")
A5: No | B5: 案件 | C5: タスク名 | D5: 担当 | E5: 開始 | F5: 期限 | G5: 進捗 | H5: 状態 | I5: =$C$2 -> 46266 | J5: =I5+1 -> 46267 | K5: =J5+1 -> 46268 | L5: =K5+1 -> 46269 | M5: =L5+1 -> 46270 | N5: =M5+1 -> 46271 | O5: =N5+1 -> 46272 | P5: =O5+1 -> 46273 | Q5: =P5+1 -> 46274 | ... BZ5: =BY5+1 -> 46335
A6: =IF(タスク!$D4="","",タスク!$A4) -> 1 | B6: =IF(タスク!$D4="","",タスク!$C4) -> A社_無線LAN更改 | C6: =IF(タスク!$D4="","",タスク!$D4) -> 現地調査結果のまとめ | D6: =IF(タスク!$D4="","",タスク!$E4) -> 新人A | E6: =IF(タスク!$D4="","",IF(タスク!$F4="","",タスク!$F4)) -> 46266 | F6: =IF(タスク!$D4="","",IF(タスク!$G4="","",タスク!$G4)) -> 46270 | G6: =IF(タスク!$D4="","",IF(タスク!$H4="完了",1,IF(タスク!$I4="",0,タスク!$I4))) -> 0.4 | H6: =IF(タスク!$D4="","",タスク!$H4) -> 進行中
A7: =IF(タスク!$D5="","",タスク!$A5) -> 2 | B7: =IF(タスク!$D5="","",タスク!$C5) -> A社_無線LAN更改 | C7: =IF(タスク!$D5="","",タスク!$D5) -> 機器設定パラメータシート作成 | D7: =IF(タスク!$D5="","",タスク!$E5) -> 新人A | E7: =IF(タスク!$D5="","",IF(タスク!$F5="","",タスク!$F5)) -> 46269 | F7: =IF(タスク!$D5="","",IF(タスク!$G5="","",タスク!$G5)) -> 46273 | G7: =IF(タスク!$D5="","",IF(タスク!$H5="完了",1,IF(タスク!$I5="",0,タスク!$I5))) -> 0.9 | H7: =IF(タスク!$D5="","",タスク!$H5) -> レビュー待ち
A8: =IF(タスク!$D6="","",タスク!$A6) -> 3 | B8: =IF(タスク!$D6="","",タスク!$C6) -> A社_FW更改 | C8: =IF(タスク!$D6="","",タスク!$D6) -> 検証構成図の作成 | D8: =IF(タスク!$D6="","",タスク!$E6) -> 新人B | E8: =IF(タスク!$D6="","",IF(タスク!$F6="","",タスク!$F6)) -> 46272 | F8: =IF(タスク!$D6="","",IF(タスク!$G6="","",タスク!$G6)) -> 46277 | G8: =IF(タスク!$D6="","",IF(タスク!$H6="完了",1,IF(タスク!$I6="",0,タスク!$I6))) -> 0.3 | H8: =IF(タスク!$D6="","",タスク!$H6) -> 進行中
A9: =IF(タスク!$D7="","",タスク!$A7) -> 4 | B9: =IF(タスク!$D7="","",タスク!$C7) -> B社_監視導入 | C9: =IF(タスク!$D7="","",タスク!$D7) -> 監視項目一覧のドラフト | D9: =IF(タスク!$D7="","",タスク!$E7) -> 新人B | E9: =IF(タスク!$D7="","",IF(タスク!$F7="","",タスク!$F7)) -> 46267 | F9: =IF(タスク!$D7="","",IF(タスク!$G7="","",タスク!$G7)) -> 46270 | G9: =IF(タスク!$D7="","",IF(タスク!$H7="完了",1,IF(タスク!$I7="",0,タスク!$I7))) -> 1 | H9: =IF(タスク!$D7="","",タスク!$H7) -> 完了
A10: =IF(タスク!$D8="","",タスク!$A8) -> 5 | B10: =IF(タスク!$D8="","",タスク!$C8) -> B社_監視導入 | C10: =IF(タスク!$D8="","",タスク!$D8) -> 死活監視の検証 | D10: =IF(タスク!$D8="","",タスク!$E8) -> 新人A | E10: =IF(タスク!$D8="","",IF(タスク!$F8="","",タスク!$F8)) -> 46274 | F10: =IF(タスク!$D8="","",IF(タスク!$G8="","",タスク!$G8)) -> 46281 | G10: =IF(タスク!$D8="","",IF(タスク!$H8="完了",1,IF(タスク!$I8="",0,タスク!$I8))) -> 0 | H10: =IF(タスク!$D8="","",タスク!$H8) -> 未着手
A11: =IF(タスク!$D9="","",タスク!$A9) | B11: =IF(タスク!$D9="","",タスク!$C9) | C11: =IF(タスク!$D9="","",タスク!$D9) | D11: =IF(タスク!$D9="","",タスク!$E9) | E11: =IF(タスク!$D9="","",IF(タスク!$F9="","",タスク!$F9)) | F11: =IF(タスク!$D9="","",IF(タスク!$G9="","",タスク!$G9)) | G11: =IF(タスク!$D9="","",IF(タスク!$H9="完了",1,IF(タスク!$I9="",0,タスク!$I9))) | H11: =IF(タスク!$D9="","",タスク!$H9)
A12: =IF(タスク!$D10="","",タスク!$A10) | B12: =IF(タスク!$D10="","",タスク!$C10) | C12: =IF(タスク!$D10="","",タスク!$D10) | D12: =IF(タスク!$D10="","",タスク!$E10) | E12: =IF(タスク!$D10="","",IF(タスク!$F10="","",タスク!$F10)) | F12: =IF(タスク!$D10="","",IF(タスク!$G10="","",タスク!$G10)) | G12: =IF(タスク!$D10="","",IF(タスク!$H10="完了",1,IF(タスク!$I10="",0,タスク!$I10))) | H12: =IF(タスク!$D10="","",タスク!$H10)
A13: =IF(タスク!$D11="","",タスク!$A11) | B13: =IF(タスク!$D11="","",タスク!$C11) | C13: =IF(タスク!$D11="","",タスク!$D11) | D13: =IF(タスク!$D11="","",タスク!$E11) | E13: =IF(タスク!$D11="","",IF(タスク!$F11="","",タスク!$F11)) | F13: =IF(タスク!$D11="","",IF(タスク!$G11="","",タスク!$G11)) | G13: =IF(タスク!$D11="","",IF(タスク!$H11="完了",1,IF(タスク!$I11="",0,タスク!$I11))) | H13: =IF(タスク!$D11="","",タスク!$H11)
A14: =IF(タスク!$D12="","",タスク!$A12) | B14: =IF(タスク!$D12="","",タスク!$C12) | C14: =IF(タスク!$D12="","",タスク!$D12) | D14: =IF(タスク!$D12="","",タスク!$E12) | E14: =IF(タスク!$D12="","",IF(タスク!$F12="","",タスク!$F12)) | F14: =IF(タスク!$D12="","",IF(タスク!$G12="","",タスク!$G12)) | G14: =IF(タスク!$D12="","",IF(タスク!$H12="完了",1,IF(タスク!$I12="",0,タスク!$I12))) | H14: =IF(タスク!$D12="","",タスク!$H12)
A15: =IF(タスク!$D13="","",タスク!$A13) | B15: =IF(タスク!$D13="","",タスク!$C13) | C15: =IF(タスク!$D13="","",タスク!$D13) | D15: =IF(タスク!$D13="","",タスク!$E13) | E15: =IF(タスク!$D13="","",IF(タスク!$F13="","",タスク!$F13)) | F15: =IF(タスク!$D13="","",IF(タスク!$G13="","",タスク!$G13)) | G15: =IF(タスク!$D13="","",IF(タスク!$H13="完了",1,IF(タスク!$I13="",0,タスク!$I13))) | H15: =IF(タスク!$D13="","",タスク!$H13)
A16: =IF(タスク!$D14="","",タスク!$A14) | B16: =IF(タスク!$D14="","",タスク!$C14) | C16: =IF(タスク!$D14="","",タスク!$D14) | D16: =IF(タスク!$D14="","",タスク!$E14) | E16: =IF(タスク!$D14="","",IF(タスク!$F14="","",タスク!$F14)) | F16: =IF(タスク!$D14="","",IF(タスク!$G14="","",タスク!$G14)) | G16: =IF(タスク!$D14="","",IF(タスク!$H14="完了",1,IF(タスク!$I14="",0,タスク!$I14))) | H16: =IF(タスク!$D14="","",タスク!$H14)
A17: =IF(タスク!$D15="","",タスク!$A15) | B17: =IF(タスク!$D15="","",タスク!$C15) | C17: =IF(タスク!$D15="","",タスク!$D15) | D17: =IF(タスク!$D15="","",タスク!$E15) | E17: =IF(タスク!$D15="","",IF(タスク!$F15="","",タスク!$F15)) | F17: =IF(タスク!$D15="","",IF(タスク!$G15="","",タスク!$G15)) | G17: =IF(タスク!$D15="","",IF(タスク!$H15="完了",1,IF(タスク!$I15="",0,タスク!$I15))) | H17: =IF(タスク!$D15="","",タスク!$H15)
... A155: =IF(タスク!$D153="","",タスク!$A153) | B155: =IF(タスク!$D153="","",タスク!$C153) | C155: =IF(タスク!$D153="","",タスク!$D153) | D155: =IF(タスク!$D153="","",タスク!$E153) | E155: =IF(タスク!$D153="","",IF(タスク!$F153="","",タスク!$F153)) | F155: =IF(タスク!$D153="","",IF(タスク!$G153="","",タスク!$G153)) | G155: =IF(タスク!$D153="","",IF(タスク!$H153="完了",1,IF(タスク!$I153="",0,タスク!$I153))) | H155: =IF(タスク!$D153="","",タスク!$H153)

Sheet 案件サマリ
A1: root@team:~# ./projects --overview
A2: 全て自動計算。案件の追加は「案件マスタ」シートで。
A3: 顧客 | B3: 案件 | C3: タスク数 | D3: 完了 | E3: 🔴超過 | F3: 🟡今日 | G3: レビュー待ち | H3: 進捗率 | I3: 予定工数h | J3: 実績工数h | K3: 差分h | L3: 状況
A4: =IF(案件マスタ!$B4="","",案件マスタ!$A4) -> A社 | B4: =IF(案件マスタ!$B4="","",案件マスタ!$B4) -> A社_無線LAN更改 | C4: =IF($B4="","",COUNTIF(タスク!$C$4:$C$503,$B4)) -> 2 | D4: =IF($B4="","",COUNTIFS(タスク!$C$4:$C$503,$B4,タスク!$H$4:$H$503,"完了")) -> 0 | E4: =IF($B4="","",COUNTIFS(タスク!$C$4:$C$503,$B4,タスク!$J$4:$J$503,"🔴 OVERDUE")) -> 1 | F4: =IF($B4="","",COUNTIFS(タスク!$C$4:$C$503,$B4,タスク!$J$4:$J$503,"🟡 TODAY")) -> 1 | G4: =IF($B4="","",COUNTIFS(タスク!$C$4:$C$503,$B4,タスク!$H$4:$H$503,"レビュー待ち")) -> 1 | H4: =IF($B4="","",IF(C4=0,"",D4/C4)) -> 0 | I4: =IF($B4="","",SUMIFS(タスク!$K$4:$K$503,タスク!$C$4:$C$503,$B4)) -> 20 | J4: =IF($B4="","",SUMIFS(工数ログ!$E$4:$E$1003,工数ログ!$C$4:$C$1003,$B4)) -> 7.5 | K4: =IF($B4="","",J4-I4) -> -12.5 | L4: =IF($B4="","",IF(E4>0,"⚠ DELAYED",IF(F4>0,"△ DUE TODAY","● ON TRACK"))) -> ⚠ DELAYED
A5: =IF(案件マスタ!$B5="","",案件マスタ!$A5) -> A社 | B5: =IF(案件マスタ!$B5="","",案件マスタ!$B5) -> A社_FW更改 | C5: =IF($B5="","",COUNTIF(タスク!$C$4:$C$503,$B5)) -> 1 | D5: =IF($B5="","",COUNTIFS(タスク!$C$4:$C$503,$B5,タスク!$H$4:$H$503,"完了")) -> 0 | E5: =IF($B5="","",COUNTIFS(タスク!$C$4:$C$503,$B5,タスク!$J$4:$J$503,"🔴 OVERDUE")) -> 0 | F5: =IF($B5="","",COUNTIFS(タスク!$C$4:$C$503,$B5,タスク!$J$4:$J$503,"🟡 TODAY")) -> 0 | G5: =IF($B5="","",COUNTIFS(タスク!$C$4:$C$503,$B5,タスク!$H$4:$H$503,"レビュー待ち")) -> 0 | H5: =IF($B5="","",IF(C5=0,"",D5/C5)) -> 0 | I5: =IF($B5="","",SUMIFS(タスク!$K$4:$K$503,タスク!$C$4:$C$503,$B5)) -> 6 | J5: =IF($B5="","",SUMIFS(工数ログ!$E$4:$E$1003,工数ログ!$C$4:$C$1003,$B5)) -> 1.5 | K5: =IF($B5="","",J5-I5) -> -4.5 | L5: =IF($B5="","",IF(E5>0,"⚠ DELAYED",IF(F5>0,"△ DUE TODAY","● ON TRACK"))) -> ● ON TRACK
A6: =IF(案件マスタ!$B6="","",案件マスタ!$A6) -> B社 | B6: =IF(案件マスタ!$B6="","",案件マスタ!$B6) -> B社_監視導入 | C6: =IF($B6="","",COUNTIF(タスク!$C$4:$C$503,$B6)) -> 2 | D6: =IF($B6="","",COUNTIFS(タスク!$C$4:$C$503,$B6,タスク!$H$4:$H$503,"完了")) -> 1 | E6: =IF($B6="","",COUNTIFS(タスク!$C$4:$C$503,$B6,タスク!$J$4:$J$503,"🔴 OVERDUE")) -> 0 | F6: =IF($B6="","",COUNTIFS(タスク!$C$4:$C$503,$B6,タスク!$J$4:$J$503,"🟡 TODAY")) -> 0 | G6: =IF($B6="","",COUNTIFS(タスク!$C$4:$C$503,$B6,タスク!$H$4:$H$503,"レビュー待ち")) -> 0 | H6: =IF($B6="","",IF(C6=0,"",D6/C6)) -> 0.5 | I6: =IF($B6="","",SUMIFS(タスク!$K$4:$K$503,タスク!$C$4:$C$503,$B6)) -> 14 | J6: =IF($B6="","",SUMIFS(工数ログ!$E$4:$E$1003,工数ログ!$C$4:$C$1003,$B6)) -> 4 | K6: =IF($B6="","",J6-I6) -> -10 | L6: =IF($B6="","",IF(E6>0,"⚠ DELAYED",IF(F6>0,"△ DUE TODAY","● ON TRACK"))) -> ● ON TRACK
A7: =IF(案件マスタ!$B7="","",案件マスタ!$A7) | B7: =IF(案件マスタ!$B7="","",案件マスタ!$B7) | C7: =IF($B7="","",COUNTIF(タスク!$C$4:$C$503,$B7)) | D7: =IF($B7="","",COUNTIFS(タスク!$C$4:$C$503,$B7,タスク!$H$4:$H$503,"完了")) | E7: =IF($B7="","",COUNTIFS(タスク!$C$4:$C$503,$B7,タスク!$J$4:$J$503,"🔴 OVERDUE")) | F7: =IF($B7="","",COUNTIFS(タスク!$C$4:$C$503,$B7,タスク!$J$4:$J$503,"🟡 TODAY")) | G7: =IF($B7="","",COUNTIFS(タスク!$C$4:$C$503,$B7,タスク!$H$4:$H$503,"レビュー待ち")) | H7: =IF($B7="","",IF(C7=0,"",D7/C7)) | I7: =IF($B7="","",SUMIFS(タスク!$K$4:$K$503,タスク!$C$4:$C$503,$B7)) | J7: =IF($B7="","",SUMIFS(工数ログ!$E$4:$E$1003,工数ログ!$C$4:$C$1003,$B7)) | K7: =IF($B7="","",J7-I7) | L7: =IF($B7="","",IF(E7>0,"⚠ DELAYED",IF(F7>0,"△ DUE TODAY","● ON TRACK")))
A8: =IF(案件マスタ!$B8="","",案件マスタ!$A8) | B8: =IF(案件マスタ!$B8="","",案件マスタ!$B8) | C8: =IF($B8="","",COUNTIF(タスク!$C$4:$C$503,$B8)) | D8: =IF($B8="","",COUNTIFS(タスク!$C$4:$C$503,$B8,タスク!$H$4:$H$503,"完了")) | E8: =IF($B8="","",COUNTIFS(タスク!$C$4:$C$503,$B8,タスク!$J$4:$J$503,"🔴 OVERDUE")) | F8: =IF($B8="","",COUNTIFS(タスク!$C$4:$C$503,$B8,タスク!$J$4:$J$503,"🟡 TODAY")) | G8: =IF($B8="","",COUNTIFS(タスク!$C$4:$C$503,$B8,タスク!$H$4:$H$503,"レビュー待ち")) | H8: =IF($B8="","",IF(C8=0,"",D8/C8)) | I8: =IF($B8="","",SUMIFS(タスク!$K$4:$K$503,タスク!$C$4:$C$503,$B8)) | J8: =IF($B8="","",SUMIFS(工数ログ!$E$4:$E$1003,工数ログ!$C$4:$C$1003,$B8)) | K8: =IF($B8="","",J8-I8) | L8: =IF($B8="","",IF(E8>0,"⚠ DELAYED",IF(F8>0,"△ DUE TODAY","● ON TRACK")))
A9: =IF(案件マスタ!$B9="","",案件マスタ!$A9) | B9: =IF(案件マスタ!$B9="","",案件マスタ!$B9) | C9: =IF($B9="","",COUNTIF(タスク!$C$4:$C$503,$B9)) | D9: =IF($B9="","",COUNTIFS(タスク!$C$4:$C$503,$B9,タスク!$H$4:$H$503,"完了")) | E9: =IF($B9="","",COUNTIFS(タスク!$C$4:$C$503,$B9,タスク!$J$4:$J$503,"🔴 OVERDUE")) | F9: =IF($B9="","",COUNTIFS(タスク!$C$4:$C$503,$B9,タスク!$J$4:$J$503,"🟡 TODAY")) | G9: =IF($B9="","",COUNTIFS(タスク!$C$4:$C$503,$B9,タスク!$H$4:$H$503,"レビュー待ち")) | H9: =IF($B9="","",IF(C9=0,"",D9/C9)) | I9: =IF($B9="","",SUMIFS(タスク!$K$4:$K$503,タスク!$C$4:$C$503,$B9)) | J9: =IF($B9="","",SUMIFS(工数ログ!$E$4:$E$1003,工数ログ!$C$4:$C$1003,$B9)) | K9: =IF($B9="","",J9-I9) | L9: =IF($B9="","",IF(E9>0,"⚠ DELAYED",IF(F9>0,"△ DUE TODAY","● ON TRACK")))
A10: =IF(案件マスタ!$B10="","",案件マスタ!$A10) | B10: =IF(案件マスタ!$B10="","",案件マスタ!$B10) | C10: =IF($B10="","",COUNTIF(タスク!$C$4:$C$503,$B10)) | D10: =IF($B10="","",COUNTIFS(タスク!$C$4:$C$503,$B10,タスク!$H$4:$H$503,"完了")) | E10: =IF($B10="","",COUNTIFS(タスク!$C$4:$C$503,$B10,タスク!$J$4:$J$503,"🔴 OVERDUE")) | F10: =IF($B10="","",COUNTIFS(タスク!$C$4:$C$503,$B10,タスク!$J$4:$J$503,"🟡 TODAY")) | G10: =IF($B10="","",COUNTIFS(タスク!$C$4:$C$503,$B10,タスク!$H$4:$H$503,"レビュー待ち")) | H10: =IF($B10="","",IF(C10=0,"",D10/C10)) | I10: =IF($B10="","",SUMIFS(タスク!$K$4:$K$503,タスク!$C$4:$C$503,$B10)) | J10: =IF($B10="","",SUMIFS(工数ログ!$E$4:$E$1003,工数ログ!$C$4:$C$1003,$B10)) | K10: =IF($B10="","",J10-I10) | L10: =IF($B10="","",IF(E10>0,"⚠ DELAYED",IF(F10>0,"△ DUE TODAY","● ON TRACK")))
A11: =IF(案件マスタ!$B11="","",案件マスタ!$A11) | B11: =IF(案件マスタ!$B11="","",案件マスタ!$B11) | C11: =IF($B11="","",COUNTIF(タスク!$C$4:$C$503,$B11)) | D11: =IF($B11="","",COUNTIFS(タスク!$C$4:$C$503,$B11,タスク!$H$4:$H$503,"完了")) | E11: =IF($B11="","",COUNTIFS(タスク!$C$4:$C$503,$B11,タスク!$J$4:$J$503,"🔴 OVERDUE")) | F11: =IF($B11="","",COUNTIFS(タスク!$C$4:$C$503,$B11,タスク!$J$4:$J$503,"🟡 TODAY")) | G11: =IF($B11="","",COUNTIFS(タスク!$C$4:$C$503,$B11,タスク!$H$4:$H$503,"レビュー待ち")) | H11: =IF($B11="","",IF(C11=0,"",D11/C11)) | I11: =IF($B11="","",SUMIFS(タスク!$K$4:$K$503,タスク!$C$4:$C$503,$B11)) | J11: =IF($B11="","",SUMIFS(工数ログ!$E$4:$E$1003,工数ログ!$C$4:$C$1003,$B11)) | K11: =IF($B11="","",J11-I11) | L11: =IF($B11="","",IF(E11>0,"⚠ DELAYED",IF(F11>0,"△ DUE TODAY","● ON TRACK")))
A12: =IF(案件マスタ!$B12="","",案件マスタ!$A12) | B12: =IF(案件マスタ!$B12="","",案件マスタ!$B12) | C12: =IF($B12="","",COUNTIF(タスク!$C$4:$C$503,$B12)) | D12: =IF($B12="","",COUNTIFS(タスク!$C$4:$C$503,$B12,タスク!$H$4:$H$503,"完了")) | E12: =IF($B12="","",COUNTIFS(タスク!$C$4:$C$503,$B12,タスク!$J$4:$J$503,"🔴 OVERDUE")) | F12: =IF($B12="","",COUNTIFS(タスク!$C$4:$C$503,$B12,タスク!$J$4:$J$503,"🟡 TODAY")) | G12: =IF($B12="","",COUNTIFS(タスク!$C$4:$C$503,$B12,タスク!$H$4:$H$503,"レビュー待ち")) | H12: =IF($B12="","",IF(C12=0,"",D12/C12)) | I12: =IF($B12="","",SUMIFS(タスク!$K$4:$K$503,タスク!$C$4:$C$503,$B12)) | J12: =IF($B12="","",SUMIFS(工数ログ!$E$4:$E$1003,工数ログ!$C$4:$C$1003,$B12)) | K12: =IF($B12="","",J12-I12) | L12: =IF($B12="","",IF(E12>0,"⚠ DELAYED",IF(F12>0,"△ DUE TODAY","● ON TRACK")))
A13: =IF(案件マスタ!$B13="","",案件マスタ!$A13) | B13: =IF(案件マスタ!$B13="","",案件マスタ!$B13) | C13: =IF($B13="","",COUNTIF(タスク!$C$4:$C$503,$B13)) | D13: =IF($B13="","",COUNTIFS(タスク!$C$4:$C$503,$B13,タスク!$H$4:$H$503,"完了")) | E13: =IF($B13="","",COUNTIFS(タスク!$C$4:$C$503,$B13,タスク!$J$4:$J$503,"🔴 OVERDUE")) | F13: =IF($B13="","",COUNTIFS(タスク!$C$4:$C$503,$B13,タスク!$J$4:$J$503,"🟡 TODAY")) | G13: =IF($B13="","",COUNTIFS(タスク!$C$4:$C$503,$B13,タスク!$H$4:$H$503,"レビュー待ち")) | H13: =IF($B13="","",IF(C13=0,"",D13/C13)) | I13: =IF($B13="","",SUMIFS(タスク!$K$4:$K$503,タスク!$C$4:$C$503,$B13)) | J13: =IF($B13="","",SUMIFS(工数ログ!$E$4:$E$1003,工数ログ!$C$4:$C$1003,$B13)) | K13: =IF($B13="","",J13-I13) | L13: =IF($B13="","",IF(E13>0,"⚠ DELAYED",IF(F13>0,"△ DUE TODAY","● ON TRACK")))
A14: =IF(案件マスタ!$B14="","",案件マスタ!$A14) | B14: =IF(案件マスタ!$B14="","",案件マスタ!$B14) | C14: =IF($B14="","",COUNTIF(タスク!$C$4:$C$503,$B14)) | D14: =IF($B14="","",COUNTIFS(タスク!$C$4:$C$503,$B14,タスク!$H$4:$H$503,"完了")) | E14: =IF($B14="","",COUNTIFS(タスク!$C$4:$C$503,$B14,タスク!$J$4:$J$503,"🔴 OVERDUE")) | F14: =IF($B14="","",COUNTIFS(タスク!$C$4:$C$503,$B14,タスク!$J$4:$J$503,"🟡 TODAY")) | G14: =IF($B14="","",COUNTIFS(タスク!$C$4:$C$503,$B14,タスク!$H$4:$H$503,"レビュー待ち")) | H14: =IF($B14="","",IF(C14=0,"",D14/C14)) | I14: =IF($B14="","",SUMIFS(タスク!$K$4:$K$503,タスク!$C$4:$C$503,$B14)) | J14: =IF($B14="","",SUMIFS(工数ログ!$E$4:$E$1003,工数ログ!$C$4:$C$1003,$B14)) | K14: =IF($B14="","",J14-I14) | L14: =IF($B14="","",IF(E14>0,"⚠ DELAYED",IF(F14>0,"△ DUE TODAY","● ON TRACK")))
A15: =IF(案件マスタ!$B15="","",案件マスタ!$A15) | B15: =IF(案件マスタ!$B15="","",案件マスタ!$B15) | C15: =IF($B15="","",COUNTIF(タスク!$C$4:$C$503,$B15)) | D15: =IF($B15="","",COUNTIFS(タスク!$C$4:$C$503,$B15,タスク!$H$4:$H$503,"完了")) | E15: =IF($B15="","",COUNTIFS(タスク!$C$4:$C$503,$B15,タスク!$J$4:$J$503,"🔴 OVERDUE")) | F15: =IF($B15="","",COUNTIFS(タスク!$C$4:$C$503,$B15,タスク!$J$4:$J$503,"🟡 TODAY")) | G15: =IF($B15="","",COUNTIFS(タスク!$C$4:$C$503,$B15,タスク!$H$4:$H$503,"レビュー待ち")) | H15: =IF($B15="","",IF(C15=0,"",D15/C15)) | I15: =IF($B15="","",SUMIFS(タスク!$K$4:$K$503,タスク!$C$4:$C$503,$B15)) | J15: =IF($B15="","",SUMIFS(工数ログ!$E$4:$E$1003,工数ログ!$C$4:$C$1003,$B15)) | K15: =IF($B15="","",J15-I15) | L15: =IF($B15="","",IF(E15>0,"⚠ DELAYED",IF(F15>0,"△ DUE TODAY","● ON TRACK")))
... A23: =IF(案件マスタ!$B23="","",案件マスタ!$A23) | B23: =IF(案件マスタ!$B23="","",案件マスタ!$B23) | C23: =IF($B23="","",COUNTIF(タスク!$C$4:$C$503,$B23)) | D23: =IF($B23="","",COUNTIFS(タスク!$C$4:$C$503,$B23,タスク!$H$4:$H$503,"完了")) | E23: =IF($B23="","",COUNTIFS(タスク!$C$4:$C$503,$B23,タスク!$J$4:$J$503,"🔴 OVERDUE")) | F23: =IF($B23="","",COUNTIFS(タスク!$C$4:$C$503,$B23,タスク!$J$4:$J$503,"🟡 TODAY")) | G23: =IF($B23="","",COUNTIFS(タスク!$C$4:$C$503,$B23,タスク!$H$4:$H$503,"レビュー待ち")) | H23: =IF($B23="","",IF(C23=0,"",D23/C23)) | I23: =IF($B23="","",SUMIFS(タスク!$K$4:$K$503,タスク!$C$4:$C$503,$B23)) | J23: =IF($B23="","",SUMIFS(工数ログ!$E$4:$E$1003,工数ログ!$C$4:$C$1003,$B23)) | K23: =IF($B23="","",J23-I23) | L23: =IF($B23="","",IF(E23>0,"⚠ DELAYED",IF(F23>0,"△ DUE TODAY","● ON TRACK")))
B24: TOTAL | C24: =SUM(C4:C23) -> 5 | D24: =SUM(D4:D23) -> 1 | E24: =SUM(E4:E23) -> 1 | F24: =SUM(F4:F23) -> 1 | G24: =SUM(G4:G23) -> 1 | I24: =SUM(I4:I23) -> 40 | J24: =SUM(J4:J23) -> 13 | K24: =SUM(K4:K23) -> -27

Sheet ダッシュボード
A1: root@team:~# ./dashboard --daily-standup
A2: 朝会はこのシートを画面共有して5分で読み合わせ。全て自動計算。案件別の俯瞰は「案件サマリ」シート。
A4: 🔴 OVERDUE | B4: 🟡 TODAY | C4: 🔵 REVIEW | D4: ⚠ NO DUE | E4: IN PROGRESS | F4: 今日の総工数h
A5: =COUNTIF(タスク!$J$4:$J$503,"🔴 OVERDUE") -> 1 | B5: =COUNTIF(タスク!$J$4:$J$503,"🟡 TODAY") -> 1 | C5: =COUNTIF(タスク!$H$4:$H$503,"レビュー待ち") -> 1 | D5: =COUNTIF(タスク!$J$4:$J$503,"⚠ NO DUE") -> 0 | E5: =COUNTIF(タスク!$H$4:$H$503,"進行中") -> 2 | F5: =SUMIFS(工数ログ!$E$4:$E$1003,工数ログ!$A$4:$A$1003,TODAY()) -> 3.5
A8: > MEMBER STATUS
A9: 担当 | B9: 未着手 | C9: 進行中 | D9: レビュー待ち | E9: 🔴超過 | F9: 🟡今日 | G9: 仕掛かり計 | H9: 今日の工数h
A10: =IF(設定!$A$4="","",設定!$A$4) -> 新人A | B10: =IF(設定!$A$4="","",COUNTIFS(タスク!$E$4:$E$503,設定!$A$4,タスク!$H$4:$H$503,"未着手")) -> 1 | C10: =IF(設定!$A$4="","",COUNTIFS(タスク!$E$4:$E$503,設定!$A$4,タスク!$H$4:$H$503,"進行中")) -> 1 | D10: =IF(設定!$A$4="","",COUNTIFS(タスク!$E$4:$E$503,設定!$A$4,タスク!$H$4:$H$503,"レビュー待ち")) -> 1 | E10: =IF(設定!$A$4="","",COUNTIFS(タスク!$E$4:$E$503,設定!$A$4,タスク!$J$4:$J$503,"🔴 OVERDUE")) -> 1 | F10: =IF(設定!$A$4="","",COUNTIFS(タスク!$E$4:$E$503,設定!$A$4,タスク!$J$4:$J$503,"🟡 TODAY")) -> 1 | G10: =IF(設定!$A$4="","",B10+C10+D10) -> 3 | H10: =IF(設定!$A$4="","",SUMIFS(工数ログ!$E$4:$E$1003,工数ログ!$B$4:$B$1003,設定!$A$4,工数ログ!$A$4:$A$1003,TODAY())) -> 2
A11: =IF(設定!$A$5="","",設定!$A$5) -> 新人B | B11: =IF(設定!$A$5="","",COUNTIFS(タスク!$E$4:$E$503,設定!$A$5,タスク!$H$4:$H$503,"未着手")) -> 0 | C11: =IF(設定!$A$5="","",COUNTIFS(タスク!$E$4:$E$503,設定!$A$5,タスク!$H$4:$H$503,"進行中")) -> 1 | D11: =IF(設定!$A$5="","",COUNTIFS(タスク!$E$4:$E$503,設定!$A$5,タスク!$H$4:$H$503,"レビュー待ち")) -> 0 | E11: =IF(設定!$A$5="","",COUNTIFS(タスク!$E$4:$E$503,設定!$A$5,タスク!$J$4:$J$503,"🔴 OVERDUE")) -> 0 | F11: =IF(設定!$A$5="","",COUNTIFS(タスク!$E$4:$E$503,設定!$A$5,タスク!$J$4:$J$503,"🟡 TODAY")) -> 0 | G11: =IF(設定!$A$5="","",B11+C11+D11) -> 1 | H11: =IF(設定!$A$5="","",SUMIFS(工数ログ!$E$4:$E$1003,工数ログ!$B$4:$B$1003,設定!$A$5,工数ログ!$A$4:$A$1003,TODAY())) -> 1.5
A12: =IF(設定!$A$6="","",設定!$A$6) -> メンターX | B12: =IF(設定!$A$6="","",COUNTIFS(タスク!$E$4:$E$503,設定!$A$6,タスク!$H$4:$H$503,"未着手")) -> 0 | C12: =IF(設定!$A$6="","",COUNTIFS(タスク!$E$4:$E$503,設定!$A$6,タスク!$H$4:$H$503,"進行中")) -> 0 | D12: =IF(設定!$A$6="","",COUNTIFS(タスク!$E$4:$E$503,設定!$A$6,タスク!$H$4:$H$503,"レビュー待ち")) -> 0 | E12: =IF(設定!$A$6="","",COUNTIFS(タスク!$E$4:$E$503,設定!$A$6,タスク!$J$4:$J$503,"🔴 OVERDUE")) -> 0 | F12: =IF(設定!$A$6="","",COUNTIFS(タスク!$E$4:$E$503,設定!$A$6,タスク!$J$4:$J$503,"🟡 TODAY")) -> 0 | G12: =IF(設定!$A$6="","",B12+C12+D12) -> 0 | H12: =IF(設定!$A$6="","",SUMIFS(工数ログ!$E$4:$E$1003,工数ログ!$B$4:$B$1003,設定!$A$6,工数ログ!$A$4:$A$1003,TODAY())) -> 0
A13: =IF(設定!$A$7="","",設定!$A$7) -> リーダーY | B13: =IF(設定!$A$7="","",COUNTIFS(タスク!$E$4:$E$503,設定!$A$7,タスク!$H$4:$H$503,"未着手")) -> 0 | C13: =IF(設定!$A$7="","",COUNTIFS(タスク!$E$4:$E$503,設定!$A$7,タスク!$H$4:$H$503,"進行中")) -> 0 | D13: =IF(設定!$A$7="","",COUNTIFS(タスク!$E$4:$E$503,設定!$A$7,タスク!$H$4:$H$503,"レビュー待ち")) -> 0 | E13: =IF(設定!$A$7="","",COUNTIFS(タスク!$E$4:$E$503,設定!$A$7,タスク!$J$4:$J$503,"🔴 OVERDUE")) -> 0 | F13: =IF(設定!$A$7="","",COUNTIFS(タスク!$E$4:$E$503,設定!$A$7,タスク!$J$4:$J$503,"🟡 TODAY")) -> 0 | G13: =IF(設定!$A$7="","",B13+C13+D13) -> 0 | H13: =IF(設定!$A$7="","",SUMIFS(工数ログ!$E$4:$E$1003,工数ログ!$B$4:$B$1003,設定!$A$7,工数ログ!$A$4:$A$1003,TODAY())) -> 0
A14: =IF(設定!$A$8="","",設定!$A$8) | B14: =IF(設定!$A$8="","",COUNTIFS(タスク!$E$4:$E$503,設定!$A$8,タスク!$H$4:$H$503,"未着手")) | C14: =IF(設定!$A$8="","",COUNTIFS(タスク!$E$4:$E$503,設定!$A$8,タスク!$H$4:$H$503,"進行中")) | D14: =IF(設定!$A$8="","",COUNTIFS(タスク!$E$4:$E$503,設定!$A$8,タスク!$H$4:$H$503,"レビュー待ち")) | E14: =IF(設定!$A$8="","",COUNTIFS(タスク!$E$4:$E$503,設定!$A$8,タスク!$J$4:$J$503,"🔴 OVERDUE")) | F14: =IF(設定!$A$8="","",COUNTIFS(タスク!$E$4:$E$503,設定!$A$8,タスク!$J$4:$J$503,"🟡 TODAY")) | G14: =IF(設定!$A$8="","",B14+C14+D14) | H14: =IF(設定!$A$8="","",SUMIFS(工数ログ!$E$4:$E$1003,工数ログ!$B$4:$B$1003,設定!$A$8,工数ログ!$A$4:$A$1003,TODAY()))
A15: =IF(設定!$A$9="","",設定!$A$9) | B15: =IF(設定!$A$9="","",COUNTIFS(タスク!$E$4:$E$503,設定!$A$9,タスク!$H$4:$H$503,"未着手")) | C15: =IF(設定!$A$9="","",COUNTIFS(タスク!$E$4:$E$503,設定!$A$9,タスク!$H$4:$H$503,"進行中")) | D15: =IF(設定!$A$9="","",COUNTIFS(タスク!$E$4:$E$503,設定!$A$9,タスク!$H$4:$H$503,"レビュー待ち")) | E15: =IF(設定!$A$9="","",COUNTIFS(タスク!$E$4:$E$503,設定!$A$9,タスク!$J$4:$J$503,"🔴 OVERDUE")) | F15: =IF(設定!$A$9="","",COUNTIFS(タスク!$E$4:$E$503,設定!$A$9,タスク!$J$4:$J$503,"🟡 TODAY")) | G15: =IF(設定!$A$9="","",B15+C15+D15) | H15: =IF(設定!$A$9="","",SUMIFS(工数ログ!$E$4:$E$1003,工数ログ!$B$4:$B$1003,設定!$A$9,工数ログ!$A$4:$A$1003,TODAY()))
A16: =IF(設定!$A$10="","",設定!$A$10) | B16: =IF(設定!$A$10="","",COUNTIFS(タスク!$E$4:$E$503,設定!$A$10,タスク!$H$4:$H$503,"未着手")) | C16: =IF(設定!$A$10="","",COUNTIFS(タスク!$E$4:$E$503,設定!$A$10,タスク!$H$4:$H$503,"進行中")) | D16: =IF(設定!$A$10="","",COUNTIFS(タスク!$E$4:$E$503,設定!$A$10,タスク!$H$4:$H$503,"レビュー待ち")) | E16: =IF(設定!$A$10="","",COUNTIFS(タスク!$E$4:$E$503,設定!$A$10,タスク!$J$4:$J$503,"🔴 OVERDUE")) | F16: =IF(設定!$A$10="","",COUNTIFS(タスク!$E$4:$E$503,設定!$A$10,タスク!$J$4:$J$503,"🟡 TODAY")) | G16: =IF(設定!$A$10="","",B16+C16+D16) | H16: =IF(設定!$A$10="","",SUMIFS(工数ログ!$E$4:$E$1003,工数ログ!$B$4:$B$1003,設定!$A$10,工数ログ!$A$4:$A$1003,TODAY()))
A17: =IF(設定!$A$11="","",設定!$A$11) | B17: =IF(設定!$A$11="","",COUNTIFS(タスク!$E$4:$E$503,設定!$A$11,タスク!$H$4:$H$503,"未着手")) | C17: =IF(設定!$A$11="","",COUNTIFS(タスク!$E$4:$E$503,設定!$A$11,タスク!$H$4:$H$503,"進行中")) | D17: =IF(設定!$A$11="","",COUNTIFS(タスク!$E$4:$E$503,設定!$A$11,タスク!$H$4:$H$503,"レビュー待ち")) | E17: =IF(設定!$A$11="","",COUNTIFS(タスク!$E$4:$E$503,設定!$A$11,タスク!$J$4:$J$503,"🔴 OVERDUE")) | F17: =IF(設定!$A$11="","",COUNTIFS(タスク!$E$4:$E$503,設定!$A$11,タスク!$J$4:$J$503,"🟡 TODAY")) | G17: =IF(設定!$A$11="","",B17+C17+D17) | H17: =IF(設定!$A$11="","",SUMIFS(工数ログ!$E$4:$E$1003,工数ログ!$B$4:$B$1003,設定!$A$11,工数ログ!$A$4:$A$1003,TODAY()))
A18: =IF(設定!$A$12="","",設定!$A$12) | B18: =IF(設定!$A$12="","",COUNTIFS(タスク!$E$4:$E$503,設定!$A$12,タスク!$H$4:$H$503,"未着手")) | C18: =IF(設定!$A$12="","",COUNTIFS(タスク!$E$4:$E$503,設定!$A$12,タスク!$H$4:$H$503,"進行中")) | D18: =IF(設定!$A$12="","",COUNTIFS(タスク!$E$4:$E$503,設定!$A$12,タスク!$H$4:$H$503,"レビュー待ち")) | E18: =IF(設定!$A$12="","",COUNTIFS(タスク!$E$4:$E$503,設定!$A$12,タスク!$J$4:$J$503,"🔴 OVERDUE")) | F18: =IF(設定!$A$12="","",COUNTIFS(タスク!$E$4:$E$503,設定!$A$12,タスク!$J$4:$J$503,"🟡 TODAY")) | G18: =IF(設定!$A$12="","",B18+C18+D18) | H18: =IF(設定!$A$12="","",SUMIFS(工数ログ!$E$4:$E$1003,工数ログ!$B$4:$B$1003,設定!$A$12,工数ログ!$A$4:$A$1003,TODAY()))
A19: =IF(設定!$A$13="","",設定!$A$13) | B19: =IF(設定!$A$13="","",COUNTIFS(タスク!$E$4:$E$503,設定!$A$13,タスク!$H$4:$H$503,"未着手")) | C19: =IF(設定!$A$13="","",COUNTIFS(タスク!$E$4:$E$503,設定!$A$13,タスク!$H$4:$H$503,"進行中")) | D19: =IF(設定!$A$13="","",COUNTIFS(タスク!$E$4:$E$503,設定!$A$13,タスク!$H$4:$H$503,"レビュー待ち")) | E19: =IF(設定!$A$13="","",COUNTIFS(タスク!$E$4:$E$503,設定!$A$13,タスク!$J$4:$J$503,"🔴 OVERDUE")) | F19: =IF(設定!$A$13="","",COUNTIFS(タスク!$E$4:$E$503,設定!$A$13,タスク!$J$4:$J$503,"🟡 TODAY")) | G19: =IF(設定!$A$13="","",B19+C19+D19) | H19: =IF(設定!$A$13="","",SUMIFS(工数ログ!$E$4:$E$1003,工数ログ!$B$4:$B$1003,設定!$A$13,工数ログ!$A$4:$A$1003,TODAY()))
A21: > RULES OF ENGAGEMENT
A22: 1. 振った/振られたタスクは必ず台帳へ(口頭・Webex依頼も受けた側が登録)。案件プルダウンは案件マスタで追加
A23: 2. 期限なし禁止。1〜2日で終わる粒度に分割。開始日と予定工数hも登録する
A24: 3. 朝: 今日やるタスクを宣言 / 夕: 結果報告+工数ログに今日の時間を記録(1日の合計が今日の工数hに出る)
A25: 4. 「完了」への変更はメンターのみ(新人はレビュー待ちまで)。完了の定義を満たしているか確認
A26: 5. 仕掛かり(未着手+進行中+レビュー待ち)は1人3件まで
A27: 6. 進捗%は毎夕更新。ガントの▶(赤)が今日線より左なら遅れ=朝会で相談
A28: 7. ダイジェストメール: 手動=Alt+F8→SendDigest / 自動=設定シートでON

Sheet 月次工数
A1: root@team:~# ./workload --monthly
A2: 予定(PLAN)ブロックだけ入力。実績(ACTUAL)とGAPは工数ログから自動集計。
A3: 集計開始月→ | C3: 46266
A5: 案件 / PLAN (h) ※入力 | C5: =EDATE($C$3,0) -> 46266 | D5: =EDATE($C$3,1) -> 46296 | E5: =EDATE($C$3,2) -> 46327 | F5: =EDATE($C$3,3) -> 46357 | G5: =EDATE($C$3,4) -> 46388 | H5: =EDATE($C$3,5) -> 46419 | I5: =EDATE($C$3,6) -> 46447 | J5: =EDATE($C$3,7) -> 46478 | K5: =EDATE($C$3,8) -> 46508 | L5: =EDATE($C$3,9) -> 46539 | M5: =EDATE($C$3,10) -> 46569 | N5: =EDATE($C$3,11) -> 46600
A6: =IF(案件マスタ!$B4="","",案件マスタ!$B4) -> A社_無線LAN更改 | C6: 40
A7: =IF(案件マスタ!$B5="","",案件マスタ!$B5) -> A社_FW更改 | C7: 24
A8: =IF(案件マスタ!$B6="","",案件マスタ!$B6) -> B社_監視導入 | C8: 16
A9: =IF(案件マスタ!$B7="","",案件マスタ!$B7)
A10: =IF(案件マスタ!$B8="","",案件マスタ!$B8)
A11: =IF(案件マスタ!$B9="","",案件マスタ!$B9)
A12: =IF(案件マスタ!$B10="","",案件マスタ!$B10)
A13: =IF(案件マスタ!$B11="","",案件マスタ!$B11)
A14: =IF(案件マスタ!$B12="","",案件マスタ!$B12)
A15: =IF(案件マスタ!$B13="","",案件マスタ!$B13)
A16: =IF(案件マスタ!$B14="","",案件マスタ!$B14)
A17: =IF(案件マスタ!$B15="","",案件マスタ!$B15)
A18: =IF(案件マスタ!$B16="","",案件マスタ!$B16)
A19: =IF(案件マスタ!$B17="","",案件マスタ!$B17)
A20: =IF(案件マスタ!$B18="","",案件マスタ!$B18)
... A25: =IF(案件マスタ!$B23="","",案件マスタ!$B23)
A26: TOTAL | C26: =SUM(C6:C25) -> 80 | D26: =SUM(D6:D25) -> 0 | E26: =SUM(E6:E25) -> 0 | F26: =SUM(F6:F25) -> 0 | G26: =SUM(G6:G25) -> 0 | H26: =SUM(H6:H25) -> 0 | I26: =SUM(I6:I25) -> 0 | J26: =SUM(J6:J25) -> 0 | ... N26: =SUM(N6:N25) -> 0
A28: 案件 / ACTUAL (h) 自動 | C28: =EDATE($C$3,0) -> 46266 | D28: =EDATE($C$3,1) -> 46296 | E28: =EDATE($C$3,2) -> 46327 | F28: =EDATE($C$3,3) -> 46357 | G28: =EDATE($C$3,4) -> 46388 | H28: =EDATE($C$3,5) -> 46419 | I28: =EDATE($C$3,6) -> 46447 | J28: =EDATE($C$3,7) -> 46478 | K28: =EDATE($C$3,8) -> 46508 | L28: =EDATE($C$3,9) -> 46539 | M28: =EDATE($C$3,10) -> 46569 | N28: =EDATE($C$3,11) -> 46600
A29: =IF(案件マスタ!$B4="","",案件マスタ!$B4) -> A社_無線LAN更改 | C29: =IF($A29="","",SUMIFS(工数ログ!$E$4:$E$1003,工数ログ!$C$4:$C$1003,$A29,工数ログ!$A$4:$A$1003,">="&C$28,工数ログ!$A$4:$A$1003,"<"&EDATE(C$28,1))) -> 7.5 | D29: =IF($A29="","",SUMIFS(工数ログ!$E$4:$E$1003,工数ログ!$C$4:$C$1003,$A29,工数ログ!$A$4:$A$1003,">="&D$28,工数ログ!$A$4:$A$1003,"<"&EDATE(D$28,1))) -> 0 | E29: =IF($A29="","",SUMIFS(工数ログ!$E$4:$E$1003,工数ログ!$C$4:$C$1003,$A29,工数ログ!$A$4:$A$1003,">="&E$28,工数ログ!$A$4:$A$1003,"<"&EDATE(E$28,1))) -> 0 | F29: =IF($A29="","",SUMIFS(工数ログ!$E$4:$E$1003,工数ログ!$C$4:$C$1003,$A29,工数ログ!$A$4:$A$1003,">="&F$28,工数ログ!$A$4:$A$1003,"<"&EDATE(F$28,1))) -> 0 | G29: =IF($A29="","",SUMIFS(工数ログ!$E$4:$E$1003,工数ログ!$C$4:$C$1003,$A29,工数ログ!$A$4:$A$1003,">="&G$28,工数ログ!$A$4:$A$1003,"<"&EDATE(G$28,1))) -> 0 | H29: =IF($A29="","",SUMIFS(工数ログ!$E$4:$E$1003,工数ログ!$C$4:$C$1003,$A29,工数ログ!$A$4:$A$1003,">="&H$28,工数ログ!$A$4:$A$1003,"<"&EDATE(H$28,1))) -> 0 | I29: =IF($A29="","",SUMIFS(工数ログ!$E$4:$E$1003,工数ログ!$C$4:$C$1003,$A29,工数ログ!$A$4:$A$1003,">="&I$28,工数ログ!$A$4:$A$1003,"<"&EDATE(I$28,1))) -> 0 | J29: =IF($A29="","",SUMIFS(工数ログ!$E$4:$E$1003,工数ログ!$C$4:$C$1003,$A29,工数ログ!$A$4:$A$1003,">="&J$28,工数ログ!$A$4:$A$1003,"<"&EDATE(J$28,1))) -> 0 | ... N29: =IF($A29="","",SUMIFS(工数ログ!$E$4:$E$1003,工数ログ!$C$4:$C$1003,$A29,工数ログ!$A$4:$A$1003,">="&N$28,工数ログ!$A$4:$A$1003,"<"&EDATE(N$28,1))) -> 0
A30: =IF(案件マスタ!$B5="","",案件マスタ!$B5) -> A社_FW更改 | C30: =IF($A30="","",SUMIFS(工数ログ!$E$4:$E$1003,工数ログ!$C$4:$C$1003,$A30,工数ログ!$A$4:$A$1003,">="&C$28,工数ログ!$A$4:$A$1003,"<"&EDATE(C$28,1))) -> 1.5 | D30: =IF($A30="","",SUMIFS(工数ログ!$E$4:$E$1003,工数ログ!$C$4:$C$1003,$A30,工数ログ!$A$4:$A$1003,">="&D$28,工数ログ!$A$4:$A$1003,"<"&EDATE(D$28,1))) -> 0 | E30: =IF($A30="","",SUMIFS(工数ログ!$E$4:$E$1003,工数ログ!$C$4:$C$1003,$A30,工数ログ!$A$4:$A$1003,">="&E$28,工数ログ!$A$4:$A$1003,"<"&EDATE(E$28,1))) -> 0 | F30: =IF($A30="","",SUMIFS(工数ログ!$E$4:$E$1003,工数ログ!$C$4:$C$1003,$A30,工数ログ!$A$4:$A$1003,">="&F$28,工数ログ!$A$4:$A$1003,"<"&EDATE(F$28,1))) -> 0 | G30: =IF($A30="","",SUMIFS(工数ログ!$E$4:$E$1003,工数ログ!$C$4:$C$1003,$A30,工数ログ!$A$4:$A$1003,">="&G$28,工数ログ!$A$4:$A$1003,"<"&EDATE(G$28,1))) -> 0 | H30: =IF($A30="","",SUMIFS(工数ログ!$E$4:$E$1003,工数ログ!$C$4:$C$1003,$A30,工数ログ!$A$4:$A$1003,">="&H$28,工数ログ!$A$4:$A$1003,"<"&EDATE(H$28,1))) -> 0 | I30: =IF($A30="","",SUMIFS(工数ログ!$E$4:$E$1003,工数ログ!$C$4:$C$1003,$A30,工数ログ!$A$4:$A$1003,">="&I$28,工数ログ!$A$4:$A$1003,"<"&EDATE(I$28,1))) -> 0 | J30: =IF($A30="","",SUMIFS(工数ログ!$E$4:$E$1003,工数ログ!$C$4:$C$1003,$A30,工数ログ!$A$4:$A$1003,">="&J$28,工数ログ!$A$4:$A$1003,"<"&EDATE(J$28,1))) -> 0 | ... N30: =IF($A30="","",SUMIFS(工数ログ!$E$4:$E$1003,工数ログ!$C$4:$C$1003,$A30,工数ログ!$A$4:$A$1003,">="&N$28,工数ログ!$A$4:$A$1003,"<"&EDATE(N$28,1))) -> 0
A31: =IF(案件マスタ!$B6="","",案件マスタ!$B6) -> B社_監視導入 | C31: =IF($A31="","",SUMIFS(工数ログ!$E$4:$E$1003,工数ログ!$C$4:$C$1003,$A31,工数ログ!$A$4:$A$1003,">="&C$28,工数ログ!$A$4:$A$1003,"<"&EDATE(C$28,1))) -> 4 | D31: =IF($A31="","",SUMIFS(工数ログ!$E$4:$E$1003,工数ログ!$C$4:$C$1003,$A31,工数ログ!$A$4:$A$1003,">="&D$28,工数ログ!$A$4:$A$1003,"<"&EDATE(D$28,1))) -> 0 | E31: =IF($A31="","",SUMIFS(工数ログ!$E$4:$E$1003,工数ログ!$C$4:$C$1003,$A31,工数ログ!$A$4:$A$1003,">="&E$28,工数ログ!$A$4:$A$1003,"<"&EDATE(E$28,1))) -> 0 | F31: =IF($A31="","",SUMIFS(工数ログ!$E$4:$E$1003,工数ログ!$C$4:$C$1003,$A31,工数ログ!$A$4:$A$1003,">="&F$28,工数ログ!$A$4:$A$1003,"<"&EDATE(F$28,1))) -> 0 | G31: =IF($A31="","",SUMIFS(工数ログ!$E$4:$E$1003,工数ログ!$C$4:$C$1003,$A31,工数ログ!$A$4:$A$1003,">="&G$28,工数ログ!$A$4:$A$1003,"<"&EDATE(G$28,1))) -> 0 | H31: =IF($A31="","",SUMIFS(工数ログ!$E$4:$E$1003,工数ログ!$C$4:$C$1003,$A31,工数ログ!$A$4:$A$1003,">="&H$28,工数ログ!$A$4:$A$1003,"<"&EDATE(H$28,1))) -> 0 | I31: =IF($A31="","",SUMIFS(工数ログ!$E$4:$E$1003,工数ログ!$C$4:$C$1003,$A31,工数ログ!$A$4:$A$1003,">="&I$28,工数ログ!$A$4:$A$1003,"<"&EDATE(I$28,1))) -> 0 | J31: =IF($A31="","",SUMIFS(工数ログ!$E$4:$E$1003,工数ログ!$C$4:$C$1003,$A31,工数ログ!$A$4:$A$1003,">="&J$28,工数ログ!$A$4:$A$1003,"<"&EDATE(J$28,1))) -> 0 | ... N31: =IF($A31="","",SUMIFS(工数ログ!$E$4:$E$1003,工数ログ!$C$4:$C$1003,$A31,工数ログ!$A$4:$A$1003,">="&N$28,工数ログ!$A$4:$A$1003,"<"&EDATE(N$28,1))) -> 0
A32: =IF(案件マスタ!$B7="","",案件マスタ!$B7) | C32: =IF($A32="","",SUMIFS(工数ログ!$E$4:$E$1003,工数ログ!$C$4:$C$1003,$A32,工数ログ!$A$4:$A$1003,">="&C$28,工数ログ!$A$4:$A$1003,"<"&EDATE(C$28,1))) | D32: =IF($A32="","",SUMIFS(工数ログ!$E$4:$E$1003,工数ログ!$C$4:$C$1003,$A32,工数ログ!$A$4:$A$1003,">="&D$28,工数ログ!$A$4:$A$1003,"<"&EDATE(D$28,1))) | E32: =IF($A32="","",SUMIFS(工数ログ!$E$4:$E$1003,工数ログ!$C$4:$C$1003,$A32,工数ログ!$A$4:$A$1003,">="&E$28,工数ログ!$A$4:$A$1003,"<"&EDATE(E$28,1))) | F32: =IF($A32="","",SUMIFS(工数ログ!$E$4:$E$1003,工数ログ!$C$4:$C$1003,$A32,工数ログ!$A$4:$A$1003,">="&F$28,工数ログ!$A$4:$A$1003,"<"&EDATE(F$28,1))) | G32: =IF($A32="","",SUMIFS(工数ログ!$E$4:$E$1003,工数ログ!$C$4:$C$1003,$A32,工数ログ!$A$4:$A$1003,">="&G$28,工数ログ!$A$4:$A$1003,"<"&EDATE(G$28,1))) | H32: =IF($A32="","",SUMIFS(工数ログ!$E$4:$E$1003,工数ログ!$C$4:$C$1003,$A32,工数ログ!$A$4:$A$1003,">="&H$28,工数ログ!$A$4:$A$1003,"<"&EDATE(H$28,1))) | I32: =IF($A32="","",SUMIFS(工数ログ!$E$4:$E$1003,工数ログ!$C$4:$C$1003,$A32,工数ログ!$A$4:$A$1003,">="&I$28,工数ログ!$A$4:$A$1003,"<"&EDATE(I$28,1))) | J32: =IF($A32="","",SUMIFS(工数ログ!$E$4:$E$1003,工数ログ!$C$4:$C$1003,$A32,工数ログ!$A$4:$A$1003,">="&J$28,工数ログ!$A$4:$A$1003,"<"&EDATE(J$28,1))) | ... N32: =IF($A32="","",SUMIFS(工数ログ!$E$4:$E$1003,工数ログ!$C$4:$C$1003,$A32,工数ログ!$A$4:$A$1003,">="&N$28,工数ログ!$A$4:$A$1003,"<"&EDATE(N$28,1)))
A33: =IF(案件マスタ!$B8="","",案件マスタ!$B8) | C33: =IF($A33="","",SUMIFS(工数ログ!$E$4:$E$1003,工数ログ!$C$4:$C$1003,$A33,工数ログ!$A$4:$A$1003,">="&C$28,工数ログ!$A$4:$A$1003,"<"&EDATE(C$28,1))) | D33: =IF($A33="","",SUMIFS(工数ログ!$E$4:$E$1003,工数ログ!$C$4:$C$1003,$A33,工数ログ!$A$4:$A$1003,">="&D$28,工数ログ!$A$4:$A$1003,"<"&EDATE(D$28,1))) | E33: =IF($A33="","",SUMIFS(工数ログ!$E$4:$E$1003,工数ログ!$C$4:$C$1003,$A33,工数ログ!$A$4:$A$1003,">="&E$28,工数ログ!$A$4:$A$1003,"<"&EDATE(E$28,1))) | F33: =IF($A33="","",SUMIFS(工数ログ!$E$4:$E$1003,工数ログ!$C$4:$C$1003,$A33,工数ログ!$A$4:$A$1003,">="&F$28,工数ログ!$A$4:$A$1003,"<"&EDATE(F$28,1))) | G33: =IF($A33="","",SUMIFS(工数ログ!$E$4:$E$1003,工数ログ!$C$4:$C$1003,$A33,工数ログ!$A$4:$A$1003,">="&G$28,工数ログ!$A$4:$A$1003,"<"&EDATE(G$28,1))) | H33: =IF($A33="","",SUMIFS(工数ログ!$E$4:$E$1003,工数ログ!$C$4:$C$1003,$A33,工数ログ!$A$4:$A$1003,">="&H$28,工数ログ!$A$4:$A$1003,"<"&EDATE(H$28,1))) | I33: =IF($A33="","",SUMIFS(工数ログ!$E$4:$E$1003,工数ログ!$C$4:$C$1003,$A33,工数ログ!$A$4:$A$1003,">="&I$28,工数ログ!$A$4:$A$1003,"<"&EDATE(I$28,1))) | J33: =IF($A33="","",SUMIFS(工数ログ!$E$4:$E$1003,工数ログ!$C$4:$C$1003,$A33,工数ログ!$A$4:$A$1003,">="&J$28,工数ログ!$A$4:$A$1003,"<"&EDATE(J$28,1))) | ... N33: =IF($A33="","",SUMIFS(工数ログ!$E$4:$E$1003,工数ログ!$C$4:$C$1003,$A33,工数ログ!$A$4:$A$1003,">="&N$28,工数ログ!$A$4:$A$1003,"<"&EDATE(N$28,1)))
A34: =IF(案件マスタ!$B9="","",案件マスタ!$B9) | C34: =IF($A34="","",SUMIFS(工数ログ!$E$4:$E$1003,工数ログ!$C$4:$C$1003,$A34,工数ログ!$A$4:$A$1003,">="&C$28,工数ログ!$A$4:$A$1003,"<"&EDATE(C$28,1))) | D34: =IF($A34="","",SUMIFS(工数ログ!$E$4:$E$1003,工数ログ!$C$4:$C$1003,$A34,工数ログ!$A$4:$A$1003,">="&D$28,工数ログ!$A$4:$A$1003,"<"&EDATE(D$28,1))) | E34: =IF($A34="","",SUMIFS(工数ログ!$E$4:$E$1003,工数ログ!$C$4:$C$1003,$A34,工数ログ!$A$4:$A$1003,">="&E$28,工数ログ!$A$4:$A$1003,"<"&EDATE(E$28,1))) | F34: =IF($A34="","",SUMIFS(工数ログ!$E$4:$E$1003,工数ログ!$C$4:$C$1003,$A34,工数ログ!$A$4:$A$1003,">="&F$28,工数ログ!$A$4:$A$1003,"<"&EDATE(F$28,1))) | G34: =IF($A34="","",SUMIFS(工数ログ!$E$4:$E$1003,工数ログ!$C$4:$C$1003,$A34,工数ログ!$A$4:$A$1003,">="&G$28,工数ログ!$A$4:$A$1003,"<"&EDATE(G$28,1))) | H34: =IF($A34="","",SUMIFS(工数ログ!$E$4:$E$1003,工数ログ!$C$4:$C$1003,$A34,工数ログ!$A$4:$A$1003,">="&H$28,工数ログ!$A$4:$A$1003,"<"&EDATE(H$28,1))) | I34: =IF($A34="","",SUMIFS(工数ログ!$E$4:$E$1003,工数ログ!$C$4:$C$1003,$A34,工数ログ!$A$4:$A$1003,">="&I$28,工数ログ!$A$4:$A$1003,"<"&EDATE(I$28,1))) | J34: =IF($A34="","",SUMIFS(工数ログ!$E$4:$E$1003,工数ログ!$C$4:$C$1003,$A34,工数ログ!$A$4:$A$1003,">="&J$28,工数ログ!$A$4:$A$1003,"<"&EDATE(J$28,1))) | ... N34: =IF($A34="","",SUMIFS(工数ログ!$E$4:$E$1003,工数ログ!$C$4:$C$1003,$A34,工数ログ!$A$4:$A$1003,">="&N$28,工数ログ!$A$4:$A$1003,"<"&EDATE(N$28,1)))
A35: =IF(案件マスタ!$B10="","",案件マスタ!$B10) | C35: =IF($A35="","",SUMIFS(工数ログ!$E$4:$E$1003,工数ログ!$C$4:$C$1003,$A35,工数ログ!$A$4:$A$1003,">="&C$28,工数ログ!$A$4:$A$1003,"<"&EDATE(C$28,1))) | D35: =IF($A35="","",SUMIFS(工数ログ!$E$4:$E$1003,工数ログ!$C$4:$C$1003,$A35,工数ログ!$A$4:$A$1003,">="&D$28,工数ログ!$A$4:$A$1003,"<"&EDATE(D$28,1))) | E35: =IF($A35="","",SUMIFS(工数ログ!$E$4:$E$1003,工数ログ!$C$4:$C$1003,$A35,工数ログ!$A$4:$A$1003,">="&E$28,工数ログ!$A$4:$A$1003,"<"&EDATE(E$28,1))) | F35: =IF($A35="","",SUMIFS(工数ログ!$E$4:$E$1003,工数ログ!$C$4:$C$1003,$A35,工数ログ!$A$4:$A$1003,">="&F$28,工数ログ!$A$4:$A$1003,"<"&EDATE(F$28,1))) | G35: =IF($A35="","",SUMIFS(工数ログ!$E$4:$E$1003,工数ログ!$C$4:$C$1003,$A35,工数ログ!$A$4:$A$1003,">="&G$28,工数ログ!$A$4:$A$1003,"<"&EDATE(G$28,1))) | H35: =IF($A35="","",SUMIFS(工数ログ!$E$4:$E$1003,工数ログ!$C$4:$C$1003,$A35,工数ログ!$A$4:$A$1003,">="&H$28,工数ログ!$A$4:$A$1003,"<"&EDATE(H$28,1))) | I35: =IF($A35="","",SUMIFS(工数ログ!$E$4:$E$1003,工数ログ!$C$4:$C$1003,$A35,工数ログ!$A$4:$A$1003,">="&I$28,工数ログ!$A$4:$A$1003,"<"&EDATE(I$28,1))) | J35: =IF($A35="","",SUMIFS(工数ログ!$E$4:$E$1003,工数ログ!$C$4:$C$1003,$A35,工数ログ!$A$4:$A$1003,">="&J$28,工数ログ!$A$4:$A$1003,"<"&EDATE(J$28,1))) | ... N35: =IF($A35="","",SUMIFS(工数ログ!$E$4:$E$1003,工数ログ!$C$4:$C$1003,$A35,工数ログ!$A$4:$A$1003,">="&N$28,工数ログ!$A$4:$A$1003,"<"&EDATE(N$28,1)))
A36: =IF(案件マスタ!$B11="","",案件マスタ!$B11) | C36: =IF($A36="","",SUMIFS(工数ログ!$E$4:$E$1003,工数ログ!$C$4:$C$1003,$A36,工数ログ!$A$4:$A$1003,">="&C$28,工数ログ!$A$4:$A$1003,"<"&EDATE(C$28,1))) | D36: =IF($A36="","",SUMIFS(工数ログ!$E$4:$E$1003,工数ログ!$C$4:$C$1003,$A36,工数ログ!$A$4:$A$1003,">="&D$28,工数ログ!$A$4:$A$1003,"<"&EDATE(D$28,1))) | E36: =IF($A36="","",SUMIFS(工数ログ!$E$4:$E$1003,工数ログ!$C$4:$C$1003,$A36,工数ログ!$A$4:$A$1003,">="&E$28,工数ログ!$A$4:$A$1003,"<"&EDATE(E$28,1))) | F36: =IF($A36="","",SUMIFS(工数ログ!$E$4:$E$1003,工数ログ!$C$4:$C$1003,$A36,工数ログ!$A$4:$A$1003,">="&F$28,工数ログ!$A$4:$A$1003,"<"&EDATE(F$28,1))) | G36: =IF($A36="","",SUMIFS(工数ログ!$E$4:$E$1003,工数ログ!$C$4:$C$1003,$A36,工数ログ!$A$4:$A$1003,">="&G$28,工数ログ!$A$4:$A$1003,"<"&EDATE(G$28,1))) | H36: =IF($A36="","",SUMIFS(工数ログ!$E$4:$E$1003,工数ログ!$C$4:$C$1003,$A36,工数ログ!$A$4:$A$1003,">="&H$28,工数ログ!$A$4:$A$1003,"<"&EDATE(H$28,1))) | I36: =IF($A36="","",SUMIFS(工数ログ!$E$4:$E$1003,工数ログ!$C$4:$C$1003,$A36,工数ログ!$A$4:$A$1003,">="&I$28,工数ログ!$A$4:$A$1003,"<"&EDATE(I$28,1))) | J36: =IF($A36="","",SUMIFS(工数ログ!$E$4:$E$1003,工数ログ!$C$4:$C$1003,$A36,工数ログ!$A$4:$A$1003,">="&J$28,工数ログ!$A$4:$A$1003,"<"&EDATE(J$28,1))) | ... N36: =IF($A36="","",SUMIFS(工数ログ!$E$4:$E$1003,工数ログ!$C$4:$C$1003,$A36,工数ログ!$A$4:$A$1003,">="&N$28,工数ログ!$A$4:$A$1003,"<"&EDATE(N$28,1)))
A37: =IF(案件マスタ!$B12="","",案件マスタ!$B12) | C37: =IF($A37="","",SUMIFS(工数ログ!$E$4:$E$1003,工数ログ!$C$4:$C$1003,$A37,工数ログ!$A$4:$A$1003,">="&C$28,工数ログ!$A$4:$A$1003,"<"&EDATE(C$28,1))) | D37: =IF($A37="","",SUMIFS(工数ログ!$E$4:$E$1003,工数ログ!$C$4:$C$1003,$A37,工数ログ!$A$4:$A$1003,">="&D$28,工数ログ!$A$4:$A$1003,"<"&EDATE(D$28,1))) | E37: =IF($A37="","",SUMIFS(工数ログ!$E$4:$E$1003,工数ログ!$C$4:$C$1003,$A37,工数ログ!$A$4:$A$1003,">="&E$28,工数ログ!$A$4:$A$1003,"<"&EDATE(E$28,1))) | F37: =IF($A37="","",SUMIFS(工数ログ!$E$4:$E$1003,工数ログ!$C$4:$C$1003,$A37,工数ログ!$A$4:$A$1003,">="&F$28,工数ログ!$A$4:$A$1003,"<"&EDATE(F$28,1))) | G37: =IF($A37="","",SUMIFS(工数ログ!$E$4:$E$1003,工数ログ!$C$4:$C$1003,$A37,工数ログ!$A$4:$A$1003,">="&G$28,工数ログ!$A$4:$A$1003,"<"&EDATE(G$28,1))) | H37: =IF($A37="","",SUMIFS(工数ログ!$E$4:$E$1003,工数ログ!$C$4:$C$1003,$A37,工数ログ!$A$4:$A$1003,">="&H$28,工数ログ!$A$4:$A$1003,"<"&EDATE(H$28,1))) | I37: =IF($A37="","",SUMIFS(工数ログ!$E$4:$E$1003,工数ログ!$C$4:$C$1003,$A37,工数ログ!$A$4:$A$1003,">="&I$28,工数ログ!$A$4:$A$1003,"<"&EDATE(I$28,1))) | J37: =IF($A37="","",SUMIFS(工数ログ!$E$4:$E$1003,工数ログ!$C$4:$C$1003,$A37,工数ログ!$A$4:$A$1003,">="&J$28,工数ログ!$A$4:$A$1003,"<"&EDATE(J$28,1))) | ... N37: =IF($A37="","",SUMIFS(工数ログ!$E$4:$E$1003,工数ログ!$C$4:$C$1003,$A37,工数ログ!$A$4:$A$1003,">="&N$28,工数ログ!$A$4:$A$1003,"<"&EDATE(N$28,1)))
A38: =IF(案件マスタ!$B13="","",案件マスタ!$B13) | C38: =IF($A38="","",SUMIFS(工数ログ!$E$4:$E$1003,工数ログ!$C$4:$C$1003,$A38,工数ログ!$A$4:$A$1003,">="&C$28,工数ログ!$A$4:$A$1003,"<"&EDATE(C$28,1))) | D38: =IF($A38="","",SUMIFS(工数ログ!$E$4:$E$1003,工数ログ!$C$4:$C$1003,$A38,工数ログ!$A$4:$A$1003,">="&D$28,工数ログ!$A$4:$A$1003,"<"&EDATE(D$28,1))) | E38: =IF($A38="","",SUMIFS(工数ログ!$E$4:$E$1003,工数ログ!$C$4:$C$1003,$A38,工数ログ!$A$4:$A$1003,">="&E$28,工数ログ!$A$4:$A$1003,"<"&EDATE(E$28,1))) | F38: =IF($A38="","",SUMIFS(工数ログ!$E$4:$E$1003,工数ログ!$C$4:$C$1003,$A38,工数ログ!$A$4:$A$1003,">="&F$28,工数ログ!$A$4:$A$1003,"<"&EDATE(F$28,1))) | G38: =IF($A38="","",SUMIFS(工数ログ!$E$4:$E$1003,工数ログ!$C$4:$C$1003,$A38,工数ログ!$A$4:$A$1003,">="&G$28,工数ログ!$A$4:$A$1003,"<"&EDATE(G$28,1))) | H38: =IF($A38="","",SUMIFS(工数ログ!$E$4:$E$1003,工数ログ!$C$4:$C$1003,$A38,工数ログ!$A$4:$A$1003,">="&H$28,工数ログ!$A$4:$A$1003,"<"&EDATE(H$28,1))) | I38: =IF($A38="","",SUMIFS(工数ログ!$E$4:$E$1003,工数ログ!$C$4:$C$1003,$A38,工数ログ!$A$4:$A$1003,">="&I$28,工数ログ!$A$4:$A$1003,"<"&EDATE(I$28,1))) | J38: =IF($A38="","",SUMIFS(工数ログ!$E$4:$E$1003,工数ログ!$C$4:$C$1003,$A38,工数ログ!$A$4:$A$1003,">="&J$28,工数ログ!$A$4:$A$1003,"<"&EDATE(J$28,1))) | ... N38: =IF($A38="","",SUMIFS(工数ログ!$E$4:$E$1003,工数ログ!$C$4:$C$1003,$A38,工数ログ!$A$4:$A$1003,">="&N$28,工数ログ!$A$4:$A$1003,"<"&EDATE(N$28,1)))
A39: =IF(案件マスタ!$B14="","",案件マスタ!$B14) | C39: =IF($A39="","",SUMIFS(工数ログ!$E$4:$E$1003,工数ログ!$C$4:$C$1003,$A39,工数ログ!$A$4:$A$1003,">="&C$28,工数ログ!$A$4:$A$1003,"<"&EDATE(C$28,1))) | D39: =IF($A39="","",SUMIFS(工数ログ!$E$4:$E$1003,工数ログ!$C$4:$C$1003,$A39,工数ログ!$A$4:$A$1003,">="&D$28,工数ログ!$A$4:$A$1003,"<"&EDATE(D$28,1))) | E39: =IF($A39="","",SUMIFS(工数ログ!$E$4:$E$1003,工数ログ!$C$4:$C$1003,$A39,工数ログ!$A$4:$A$1003,">="&E$28,工数ログ!$A$4:$A$1003,"<"&EDATE(E$28,1))) | F39: =IF($A39="","",SUMIFS(工数ログ!$E$4:$E$1003,工数ログ!$C$4:$C$1003,$A39,工数ログ!$A$4:$A$1003,">="&F$28,工数ログ!$A$4:$A$1003,"<"&EDATE(F$28,1))) | G39: =IF($A39="","",SUMIFS(工数ログ!$E$4:$E$1003,工数ログ!$C$4:$C$1003,$A39,工数ログ!$A$4:$A$1003,">="&G$28,工数ログ!$A$4:$A$1003,"<"&EDATE(G$28,1))) | H39: =IF($A39="","",SUMIFS(工数ログ!$E$4:$E$1003,工数ログ!$C$4:$C$1003,$A39,工数ログ!$A$4:$A$1003,">="&H$28,工数ログ!$A$4:$A$1003,"<"&EDATE(H$28,1))) | I39: =IF($A39="","",SUMIFS(工数ログ!$E$4:$E$1003,工数ログ!$C$4:$C$1003,$A39,工数ログ!$A$4:$A$1003,">="&I$28,工数ログ!$A$4:$A$1003,"<"&EDATE(I$28,1))) | J39: =IF($A39="","",SUMIFS(工数ログ!$E$4:$E$1003,工数ログ!$C$4:$C$1003,$A39,工数ログ!$A$4:$A$1003,">="&J$28,工数ログ!$A$4:$A$1003,"<"&EDATE(J$28,1))) | ... N39: =IF($A39="","",SUMIFS(工数ログ!$E$4:$E$1003,工数ログ!$C$4:$C$1003,$A39,工数ログ!$A$4:$A$1003,">="&N$28,工数ログ!$A$4:$A$1003,"<"&EDATE(N$28,1)))
A40: =IF(案件マスタ!$B15="","",案件マスタ!$B15) | C40: =IF($A40="","",SUMIFS(工数ログ!$E$4:$E$1003,工数ログ!$C$4:$C$1003,$A40,工数ログ!$A$4:$A$1003,">="&C$28,工数ログ!$A$4:$A$1003,"<"&EDATE(C$28,1))) | D40: =IF($A40="","",SUMIFS(工数ログ!$E$4:$E$1003,工数ログ!$C$4:$C$1003,$A40,工数ログ!$A$4:$A$1003,">="&D$28,工数ログ!$A$4:$A$1003,"<"&EDATE(D$28,1))) | E40: =IF($A40="","",SUMIFS(工数ログ!$E$4:$E$1003,工数ログ!$C$4:$C$1003,$A40,工数ログ!$A$4:$A$1003,">="&E$28,工数ログ!$A$4:$A$1003,"<"&EDATE(E$28,1))) | F40: =IF($A40="","",SUMIFS(工数ログ!$E$4:$E$1003,工数ログ!$C$4:$C$1003,$A40,工数ログ!$A$4:$A$1003,">="&F$28,工数ログ!$A$4:$A$1003,"<"&EDATE(F$28,1))) | G40: =IF($A40="","",SUMIFS(工数ログ!$E$4:$E$1003,工数ログ!$C$4:$C$1003,$A40,工数ログ!$A$4:$A$1003,">="&G$28,工数ログ!$A$4:$A$1003,"<"&EDATE(G$28,1))) | H40: =IF($A40="","",SUMIFS(工数ログ!$E$4:$E$1003,工数ログ!$C$4:$C$1003,$A40,工数ログ!$A$4:$A$1003,">="&H$28,工数ログ!$A$4:$A$1003,"<"&EDATE(H$28,1))) | I40: =IF($A40="","",SUMIFS(工数ログ!$E$4:$E$1003,工数ログ!$C$4:$C$1003,$A40,工数ログ!$A$4:$A$1003,">="&I$28,工数ログ!$A$4:$A$1003,"<"&EDATE(I$28,1))) | J40: =IF($A40="","",SUMIFS(工数ログ!$E$4:$E$1003,工数ログ!$C$4:$C$1003,$A40,工数ログ!$A$4:$A$1003,">="&J$28,工数ログ!$A$4:$A$1003,"<"&EDATE(J$28,1))) | ... N40: =IF($A40="","",SUMIFS(工数ログ!$E$4:$E$1003,工数ログ!$C$4:$C$1003,$A40,工数ログ!$A$4:$A$1003,">="&N$28,工数ログ!$A$4:$A$1003,"<"&EDATE(N$28,1)))
... A48: =IF(案件マスタ!$B23="","",案件マスタ!$B23) | C48: =IF($A48="","",SUMIFS(工数ログ!$E$4:$E$1003,工数ログ!$C$4:$C$1003,$A48,工数ログ!$A$4:$A$1003,">="&C$28,工数ログ!$A$4:$A$1003,"<"&EDATE(C$28,1))) | D48: =IF($A48="","",SUMIFS(工数ログ!$E$4:$E$1003,工数ログ!$C$4:$C$1003,$A48,工数ログ!$A$4:$A$1003,">="&D$28,工数ログ!$A$4:$A$1003,"<"&EDATE(D$28,1))) | E48: =IF($A48="","",SUMIFS(工数ログ!$E$4:$E$1003,工数ログ!$C$4:$C$1003,$A48,工数ログ!$A$4:$A$1003,">="&E$28,工数ログ!$A$4:$A$1003,"<"&EDATE(E$28,1))) | F48: =IF($A48="","",SUMIFS(工数ログ!$E$4:$E$1003,工数ログ!$C$4:$C$1003,$A48,工数ログ!$A$4:$A$1003,">="&F$28,工数ログ!$A$4:$A$1003,"<"&EDATE(F$28,1))) | G48: =IF($A48="","",SUMIFS(工数ログ!$E$4:$E$1003,工数ログ!$C$4:$C$1003,$A48,工数ログ!$A$4:$A$1003,">="&G$28,工数ログ!$A$4:$A$1003,"<"&EDATE(G$28,1))) | H48: =IF($A48="","",SUMIFS(工数ログ!$E$4:$E$1003,工数ログ!$C$4:$C$1003,$A48,工数ログ!$A$4:$A$1003,">="&H$28,工数ログ!$A$4:$A$1003,"<"&EDATE(H$28,1))) | I48: =IF($A48="","",SUMIFS(工数ログ!$E$4:$E$1003,工数ログ!$C$4:$C$1003,$A48,工数ログ!$A$4:$A$1003,">="&I$28,工数ログ!$A$4:$A$1003,"<"&EDATE(I$28,1))) | J48: =IF($A48="","",SUMIFS(工数ログ!$E$4:$E$1003,工数ログ!$C$4:$C$1003,$A48,工数ログ!$A$4:$A$1003,">="&J$28,工数ログ!$A$4:$A$1003,"<"&EDATE(J$28,1))) | ... N48: =IF($A48="","",SUMIFS(工数ログ!$E$4:$E$1003,工数ログ!$C$4:$C$1003,$A48,工数ログ!$A$4:$A$1003,">="&N$28,工数ログ!$A$4:$A$1003,"<"&EDATE(N$28,1)))
A49: TOTAL | C49: =SUM(C29:C48) -> 13 | D49: =SUM(D29:D48) -> 0 | E49: =SUM(E29:E48) -> 0 | F49: =SUM(F29:F48) -> 0 | G49: =SUM(G29:G48) -> 0 | H49: =SUM(H29:H48) -> 0 | I49: =SUM(I29:I48) -> 0 | J49: =SUM(J29:J48) -> 0 | ... N49: =SUM(N29:N48) -> 0
A51: 案件 / GAP = 実績-予定 (h) 自動 | C51: =EDATE($C$3,0) -> 46266 | D51: =EDATE($C$3,1) -> 46296 | E51: =EDATE($C$3,2) -> 46327 | F51: =EDATE($C$3,3) -> 46357 | G51: =EDATE($C$3,4) -> 46388 | H51: =EDATE($C$3,5) -> 46419 | I51: =EDATE($C$3,6) -> 46447 | J51: =EDATE($C$3,7) -> 46478 | K51: =EDATE($C$3,8) -> 46508 | L51: =EDATE($C$3,9) -> 46539 | M51: =EDATE($C$3,10) -> 46569 | N51: =EDATE($C$3,11) -> 46600
A52: =IF(案件マスタ!$B4="","",案件マスタ!$B4) -> A社_無線LAN更改 | C52: =IF($A52="","",C29-C6) -> -32.5 | D52: =IF($A52="","",D29-D6) -> 0 | E52: =IF($A52="","",E29-E6) -> 0 | F52: =IF($A52="","",F29-F6) -> 0 | G52: =IF($A52="","",G29-G6) -> 0 | H52: =IF($A52="","",H29-H6) -> 0 | I52: =IF($A52="","",I29-I6) -> 0 | J52: =IF($A52="","",J29-J6) -> 0 | ... N52: =IF($A52="","",N29-N6) -> 0
A53: =IF(案件マスタ!$B5="","",案件マスタ!$B5) -> A社_FW更改 | C53: =IF($A53="","",C30-C7) -> -22.5 | D53: =IF($A53="","",D30-D7) -> 0 | E53: =IF($A53="","",E30-E7) -> 0 | F53: =IF($A53="","",F30-F7) -> 0 | G53: =IF($A53="","",G30-G7) -> 0 | H53: =IF($A53="","",H30-H7) -> 0 | I53: =IF($A53="","",I30-I7) -> 0 | J53: =IF($A53="","",J30-J7) -> 0 | ... N53: =IF($A53="","",N30-N7) -> 0
A54: =IF(案件マスタ!$B6="","",案件マスタ!$B6) -> B社_監視導入 | C54: =IF($A54="","",C31-C8) -> -12 | D54: =IF($A54="","",D31-D8) -> 0 | E54: =IF($A54="","",E31-E8) -> 0 | F54: =IF($A54="","",F31-F8) -> 0 | G54: =IF($A54="","",G31-G8) -> 0 | H54: =IF($A54="","",H31-H8) -> 0 | I54: =IF($A54="","",I31-I8) -> 0 | J54: =IF($A54="","",J31-J8) -> 0 | ... N54: =IF($A54="","",N31-N8) -> 0
...

Sheet 工数ログ
A1: root@team:~# ./timelog --append
A2: 毎日の作業時間をここに追記(1作業1行)。タスクNoはタスクシートのNo列。タスク行は削除するとNoがずれるので、削除せず「完了」にすること。
A3: 日付 | B3: 名前 | C3: 案件 | D3: タスクNo(任意) | E3: 時間h | F3: メモ
A4: 46269 | B4: 新人A | C4: A社_無線LAN更改 | D4: 1 | E4: 2.5
A5: 46270 | B5: 新人A | C5: A社_無線LAN更改 | D5: 1 | E5: 3
A6: 46268 | B6: 新人B | C6: B社_監視導入 | D6: 4 | E6: 4
A7: 46273 | B7: 新人A | C7: A社_無線LAN更改 | D7: 2 | E7: 2 | F7: レビュー指摘対応
A8: 46273 | B8: 新人B | C8: A社_FW更改 | D8: 3 | E8: 1.5

Sheet 案件マスタ
A1: root@team:~# ./projects --register
A2: 顧客と案件をここに登録するとタスク・工数ログのプルダウンとサマリ・月次工数に反映される(20枠)。案件名は重複不可。
A3: 顧客名 | B3: 案件名 | C3: 状態 | D3: 備考
A4: A社 | B4: A社_無線LAN更改 | C4: 進行中
A5: A社 | B5: A社_FW更改 | C5: 進行中
A6: B社 | B6: B社_監視導入 | C6: 進行中

Sheet 設定
A1: root@team:~# ./config
A2: 薄い青灰色のセルに入力。メンバーは上から詰めて記入(10枠)。
A3: 名前 | B3: メールアドレス | C3: 役割 | E3: > MAIL CONFIG
A4: 新人A | B4: shinjin-a@example.co.jp | C4: 新人 | E4: 自動配信(ブックを開いた時) | F4: OFF | G4: ONにすると、その日最初にブックを開いた人のOutlookから送信される
A5: 新人B | B5: shinjin-b@example.co.jp | C5: 新人 | E5: 送信モード | F5: 下書き表示 | G5: 「下書き表示」は送信前にメールが画面に出るので確認してから送れる
A6: メンターX | B6: mentor-x@example.co.jp | C6: メンター | E6: 追加宛先(任意) | G6: チームML等。空欄なら設定シートの全メンバー宛
A7: リーダーY | B7: leader-y@example.co.jp | C7: メンター | E7: 最終送信日(自動記入) | G7: マクロが記入。手で消せばその日もう一度自動配信される
E10: 状態リスト(タスクのプルダウン元。変更非推奨)
E11: 未着手
E12: 進行中
E13: レビュー待ち
A14: ※上の4行は記入例。実際のメンバーに書き換える。 | E14: 完了
